Workbook
Name UPDATE: 'Data Sheet'!$E$1

Sheet Profit & Loss
A1: ='Data Sheet'!B1 | H1: =UPDATE | M1: SCREENER.IN
A3: Narration | B3: ='Data Sheet'!B16 | C3: ='Data Sheet'!C16 | D3: ='Data Sheet'!D16 | E3: ='Data Sheet'!E16 | F3: ='Data Sheet'!F16 | G3: ='Data Sheet'!G16 | H3: ='Data Sheet'!H16 | I3: ='Data Sheet'!I16 | ... K3: ='Data Sheet'!K16 | L3: Trailing | M3: Best Case | N3: Worst Case
A4: Sales | B4: ='Data Sheet'!B17 | C4: ='Data Sheet'!C17 | D4: ='Data Sheet'!D17 | E4: ='Data Sheet'!E17 | F4: ='Data Sheet'!F17 | G4: ='Data Sheet'!G17 | H4: ='Data Sheet'!H17 | I4: ='Data Sheet'!I17 | ... K4: ='Data Sheet'!K17 | L4: =SUM(Quarters!H4:K4) | M4: =$K4+M23*K4 | N4: =$K4+N23*L4
A5: Expenses | B5: =SUM('Data Sheet'!B18,'Data Sheet'!B20:B24, -1*'Data Sheet'!B19) | C5: =SUM('Data Sheet'!C18,'Data Sheet'!C20:C24, -1*'Data Sheet'!C19) | D5: =SUM('Data Sheet'!D18,'Data Sheet'!D20:D24, -1*'Data Sheet'!D19) | E5: =SUM('Data Sheet'!E18,'Data Sheet'!E20:E24, -1*'Data Sheet'!E19) | F5: =SUM('Data Sheet'!F18,'Data Sheet'!F20:F24, -1*'Data Sheet'!F19) | G5: =SUM('Data Sheet'!G18,'Data Sheet'!G20:G24, -1*'Data Sheet'!G19) | H5: =SUM('Data Sheet'!H18,'Data Sheet'!H20:H24, -1*'Data Sheet'!H19) | I5: =SUM('Data Sheet'!I18,'Data Sheet'!I20:I24, -1*'Data Sheet'!I19) | ... K5: =SUM('Data Sheet'!K18,'Data Sheet'!K20:K24, -1*'Data Sheet'!K19) | L5: =SUM(Quarters!H5:K5) | M5: =M4-M6 | N5: =N4-N6
A6: Operating Profit | B6: =B4-B5 | C6: =C4-C5 | D6: =D4-D5 | E6: =E4-E5 | F6: =F4-F5 | G6: =G4-G5 | H6: =H4-H5 | I6: =I4-I5 | ... K6: =K4-K5 | L6: =SUM(Quarters!H6:K6) | M6: =M4*M24 | N6: =N4*N24 | O6: =SUM(C6:K6)
A7: Other Income | B7: ='Data Sheet'!B25 | C7: ='Data Sheet'!C25 | D7: ='Data Sheet'!D25 | E7: ='Data Sheet'!E25 | F7: ='Data Sheet'!F25 | G7: ='Data Sheet'!G25 | H7: ='Data Sheet'!H25 | I7: ='Data Sheet'!I25 | ... K7: ='Data Sheet'!K25 | L7: =SUM(Quarters!H7:K7) | M7: 0 | N7: 0 | O7: =SUM(B7:K7)
A8: Depreciation | B8: ='Data Sheet'!B26 | C8: ='Data Sheet'!C26 | D8: ='Data Sheet'!D26 | E8: ='Data Sheet'!E26 | F8: ='Data Sheet'!F26 | G8: ='Data Sheet'!G26 | H8: ='Data Sheet'!H26 | I8: ='Data Sheet'!I26 | ... K8: ='Data Sheet'!K26 | L8: =SUM(Quarters!H8:K8) | M8: =+$L8 | N8: =+$L8
A9: Interest | B9: ='Data Sheet'!B27 | C9: ='Data Sheet'!C27 | D9: ='Data Sheet'!D27 | E9: ='Data Sheet'!E27 | F9: ='Data Sheet'!F27 | G9: ='Data Sheet'!G27 | H9: ='Data Sheet'!H27 | I9: ='Data Sheet'!I27 | ... K9: ='Data Sheet'!K27 | L9: =SUM(Quarters!H9:K9) | M9: =+$L9 | N9: =+$L9
A10: Profit before tax | B10: ='Data Sheet'!B28 | C10: ='Data Sheet'!C28 | D10: ='Data Sheet'!D28 | E10: ='Data Sheet'!E28 | F10: ='Data Sheet'!F28 | G10: ='Data Sheet'!G28 | H10: ='Data Sheet'!H28 | I10: ='Data Sheet'!I28 | ... K10: ='Data Sheet'!K28 | L10: =SUM(Quarters!H10:K10) | M10: =M6+M7-SUM(M8:M9) | N10: =N6+N7-SUM(N8:N9)
A11: Tax | B11: ='Data Sheet'!B29 | C11: ='Data Sheet'!C29 | D11: ='Data Sheet'!D29 | E11: ='Data Sheet'!E29 | F11: ='Data Sheet'!F29 | G11: ='Data Sheet'!G29 | H11: ='Data Sheet'!H29 | I11: ='Data Sheet'!I29 | ... K11: ='Data Sheet'!K29 | L11: =SUM(Quarters!H11:K11) | M11: =IF($L10>0,$L11/$L10,0) | N11: =IF($L10>0,$L11/$L10,0) | P11: Total Profit
A12: Net profit | B12: ='Data Sheet'!B30 | C12: ='Data Sheet'!C30 | D12: ='Data Sheet'!D30 | E12: ='Data Sheet'!E30 | F12: ='Data Sheet'!F30 | G12: ='Data Sheet'!G30 | H12: ='Data Sheet'!H30 | I12: ='Data Sheet'!I30 | ... K12: ='Data Sheet'!K30 | L12: =SUM(Quarters!H12:K12) | M12: =M10-M11*M10 | N12: =N10-N11*N10 | P12: =SUM(B12:K12)
A13: EPS | B13: =IF('Data Sheet'!B93>0,B12/'Data Sheet'!B93,0) | C13: =IF('Data Sheet'!C93>0,C12/'Data Sheet'!C93,0) | D13: =IF('Data Sheet'!D93>0,D12/'Data Sheet'!D93,0) | E13: =IF('Data Sheet'!E93>0,E12/'Data Sheet'!E93,0) | F13: =IF('Data Sheet'!F93>0,F12/'Data Sheet'!F93,0) | G13: =IF('Data Sheet'!G93>0,G12/'Data Sheet'!G93,0) | H13: =IF('Data Sheet'!H93>0,H12/'Data Sheet'!H93,0) | I13: =IF('Data Sheet'!I93>0,I12/'Data Sheet'!I93,0) | ... K13: =IF('Data Sheet'!K93>0,K12/'Data Sheet'!K93,0) | L13: =IF('Data Sheet'!$B6>0,'Profit & Loss'!L12/'Data Sheet'!$B6,0) | M13: =IF('Data Sheet'!$B6>0,'Profit & Loss'!M12/'Data Sheet'!$B6,0) | N13: =IF('Data Sheet'!$B6>0,'Profit & Loss'!N12/'Data Sheet'!$B6,0)
A14: Price to earning | B14: =IF(B15>0,B15/B13,"") | C14: =IF(C15>0,C15/C13,"") | D14: =IF(D15>0,D15/D13,"") | E14: =IF(E15>0,E15/E13,"") | F14: =IF(F15>0,F15/F13,"") | G14: =IF(G15>0,G15/G13,"") | H14: =IF(H15>0,H15/H13,"") | I14: =IF(I15>0,I15/I13,"") | ... K14: =IF(K15>0,K15/K13,"") | L14: =IF(L13>0,L15/L13,0) | M14: =M25 | N14: =N25
A15: Price | B15: ='Data Sheet'!B90 | C15: ='Data Sheet'!C90 | D15: ='Data Sheet'!D90 | E15: ='Data Sheet'!E90 | F15: ='Data Sheet'!F90 | G15: ='Data Sheet'!G90 | H15: ='Data Sheet'!H90 | I15: ='Data Sheet'!I90 | ... K15: ='Data Sheet'!K90 | L15: ='Data Sheet'!B8 | M15: =M13*M14 | N15: =N13*N14
A17: RATIOS:
A18: Dividend Payout | B18: =IF('Data Sheet'!B30>0, 'Data Sheet'!B31/'Data Sheet'!B30, 0) | C18: =IF('Data Sheet'!C30>0, 'Data Sheet'!C31/'Data Sheet'!C30, 0) | D18: =IF('Data Sheet'!D30>0, 'Data Sheet'!D31/'Data Sheet'!D30, 0) | E18: =IF('Data Sheet'!E30>0, 'Data Sheet'!E31/'Data Sheet'!E30, 0) | F18: =IF('Data Sheet'!F30>0, 'Data Sheet'!F31/'Data Sheet'!F30, 0) | G18: =IF('Data Sheet'!G30>0, 'Data Sheet'!G31/'Data Sheet'!G30, 0) | H18: =IF('Data Sheet'!H30>0, 'Data Sheet'!H31/'Data Sheet'!H30, 0) | I18: =IF('Data Sheet'!I30>0, 'Data Sheet'!I31/'Data Sheet'!I30, 0) | ... K18: =IF('Data Sheet'!K30>0, 'Data Sheet'!K31/'Data Sheet'!K30, 0)
A19: OPM | B19: =IF(B6>0,B6/B4,0) | C19: =IF(C6>0,C6/C4,0) | D19: =IF(D6>0,D6/D4,0) | E19: =IF(E6>0,E6/E4,0) | F19: =IF(F6>0,F6/F4,0) | G19: =IF(G6>0,G6/G4,0) | H19: =IF(H6>0,H6/H4,0) | I19: =IF(I6>0,I6/I4,0) | ... L19: =IF(L6>0,L6/L4,0)
G22: TRENDS: | H22: 10 YEARS | I22: 7 YEARS | J22: 5 YEARS | K22: 3 YEARS | L22: RECENT | M22: BEST | N22: WORST
G23: Sales Growth | H23: =IF(B4=0,"",POWER($K4/B4,1/9)-1) | I23: =IF(D4=0,"",POWER($K4/D4,1/7)-1) | J23: =IF(F4=0,"",POWER($K4/F4,1/5)-1) | K23: =IF(H4=0,"",POWER($K4/H4, 1/3)-1) | L23: =IF(ISERROR(MAX(IF(J4=0,"",(K4-J4)/J4),IF(K4=0,"",(L4-K4)/K4))),"",MAX(IF(J4=0,"",(K4-J4)/J4),IF(K4=0,"",(L4-K4)/K4))) | M23: =MAX(K23:L23) | N23: =MIN(H23:L23)
G24: OPM | H24: =IF(SUM(B4:$K$4)=0,"",SUMPRODUCT(B19:$K$19,B4:$K$4)/SUM(B4:$K$4)) | I24: =IF(SUM(E4:$K$4)=0,"",SUMPRODUCT(E19:$K$19,E4:$K$4)/SUM(E4:$K$4)) | J24: =IF(SUM(G4:$K$4)=0,"",SUMPRODUCT(G19:$K$19,G4:$K$4)/SUM(G4:$K$4)) | K24: =IF(SUM(I4:$K$4)=0, "", SUMPRODUCT(I19:$K$19,I4:$K$4)/SUM(I4:$K$4)) | L24: =L19 | M24: =MAX(K24:L24) | N24: =MIN(H24:L24)
G25: Price to Earning | H25: =IF(ISERROR(AVERAGEIF(B14:$L14,">0")),"",AVERAGEIF(B14:$L14,">0")) | I25: =IF(ISERROR(AVERAGEIF(E14:$L14,">0")),"",AVERAGEIF(E14:$L14,">0")) | J25: =IF(ISERROR(AVERAGEIF(G14:$L14,">0")),"",AVERAGEIF(G14:$L14,">0")) | K25: =IF(ISERROR(AVERAGEIF(I14:$L14,">0")),"",AVERAGEIF(I14:$L14,">0")) | L25: =L14 | M25: =MAX(K25:L25) | N25: =MIN(H25:L25)
A27: SSGR | E27: =(E33*E28*(1-E29))-E34 | F27: =(F33*F28*(1-F29))-F34 | G27: =(G33*G28*(1-G29))-G34 | H27: =(H33*H28*(1-H29))-H34 | I27: =(I33*I28*(1-I29))-I34 | J27: =(J33*J28*(1-J29))-J34 | K27: =(K33*K28*(1-K29))-K34
A28: NPM-AVG | D28: =AVERAGE(D31,C31,B31) | E28: =AVERAGE(E31,D31,C31) | F28: =AVERAGE(F31,E31,D31) | G28: =AVERAGE(G31,F31,E31) | H28: =AVERAGE(H31,G31,F31) | I28: =AVERAGE(I31,H31,G31) | J28: =AVERAGE(J31,I31,H31) | K28: =AVERAGE(K31,J31,I31)
A29: DPR | D29: =AVERAGE(D18,C18,B18) | E29: =AVERAGE(E18,D18,C18) | F29: =AVERAGE(F18,E18,D18) | G29: =AVERAGE(G18,F18,E18) | H29: =AVERAGE(H18,G18,F18) | I29: =AVERAGE(I18,H18,G18) | J29: =AVERAGE(J18,I18,H18) | K29: =AVERAGE(K18,J18,I18)
A30: Dep | B30: =(B8/'Balance Sheet'!B10)*100 | C30: =(C8/'Balance Sheet'!C10)*100 | D30: =(D8/'Balance Sheet'!D10)*100 | E30: =(E8/'Balance Sheet'!E10)*100 | F30: =(F8/'Balance Sheet'!F10)*100 | G30: =(G8/'Balance Sheet'!G10)*100 | H30: =(H8/'Balance Sheet'!H10)*100 | I30: =(I8/'Balance Sheet'!I10)*100 | ... K30: =(K8/'Balance Sheet'!K10)*100
A31: NPM | B31: =(B12/B4)*100 | C31: =(C12/C4)*100 | D31: =(D12/D4)*100 | E31: =(E12/E4)*100 | F31: =(F12/F4)*100 | G31: =(G12/G4)*100 | H31: =(H12/H4)*100 | I31: =(I12/I4)*100 | ... K31: =(K12/K4)*100
A32: NFAT | C32: =C4/'Balance Sheet'!C28 | D32: =D4/'Balance Sheet'!D28 | E32: =E4/'Balance Sheet'!E28 | F32: =F4/'Balance Sheet'!F28 | G32: =G4/'Balance Sheet'!G28 | H32: =H4/'Balance Sheet'!H28 | I32: =I4/'Balance Sheet'!I28 | J32: =J4/'Balance Sheet'!J28 | K32: =K4/'Balance Sheet'!K28
A33: NFAT-AVG | E33: =AVERAGE(E32,D32,C32) | F33: =AVERAGE(F32,E32,D32) | G33: =AVERAGE(G32,F32,E32) | H33: =AVERAGE(H32,G32,F32) | I33: =AVERAGE(I32,H32,G32) | J33: =AVERAGE(J32,I32,H32) | K33: =AVERAGE(K32,J32,I32)
A34: Dep AVG | D34: =AVERAGE(D30,C30,B30) | E34: =AVERAGE(E30,D30,C30) | F34: =AVERAGE(F30,E30,D30) | G34: =AVERAGE(G30,F30,E30) | H34: =AVERAGE(H30,G30,F30) | I34: =AVERAGE(I30,H30,G30) | J34: =AVERAGE(J30,I30,H30) | K34: =AVERAGE(K30,J30,I30)
A36: Sales growth | C36: =((C4-B4)/B4)*100 | D36: =((D4-C4)/C4)*100 | E36: =((E4-D4)/D4)*100 | F36: =((F4-E4)/E4)*100 | G36: =((G4-F4)/F4)*100 | H36: =((H4-G4)/G4)*100 | I36: =((I4-H4)/H4)*100 | J36: =((J4-I4)/I4)*100 | K36: =((K4-J4)/J4)*100
A37: Net Profit Growth | C37: =((C12-B12)/B12)*100 | D37: =((D12-C12)/C12)*100 | E37: =((E12-D12)/D12)*100 | F37: =((F12-E12)/E12)*100 | G37: =((G12-F12)/F12)*100 | H37: =((H12-G12)/G12)*100 | I37: =((I12-H12)/H12)*100 | J37: =((J12-I12)/I12)*100 | K37: =((K12-J12)/J12)*100
A38: Raw Material Cost as a % of Sales | C38: =('Data Sheet'!B18/'Data Sheet'!B17)*100 | D38: =('Data Sheet'!C18/'Data Sheet'!C17)*100 | E38: =('Data Sheet'!D18/'Data Sheet'!D17)*100 | F38: =('Data Sheet'!E18/'Data Sheet'!E17)*100 | G38: =('Data Sheet'!F18/'Data Sheet'!F17)*100 | H38: =('Data Sheet'!G18/'Data Sheet'!G17)*100 | I38: =('Data Sheet'!H18/'Data Sheet'!H17)*100 | J38: =('Data Sheet'!I18/'Data Sheet'!I17)*100 | K38: =('Data Sheet'!J18/'Data Sheet'!J17)*100
A39: Other Income as % of Net Profit | C39: =(O7/P12)*100

Sheet Quarters
A1: ='Profit & Loss'!A1 | E1: =UPDATE | J1: SCREENER.IN
A3: Narration | B3: ='Data Sheet'!B41 | C3: ='Data Sheet'!C41 | D3: ='Data Sheet'!D41 | E3: ='Data Sheet'!E41 | F3: ='Data Sheet'!F41 | G3: ='Data Sheet'!G41 | H3: ='Data Sheet'!H41 | I3: ='Data Sheet'!I41 | ... K3: ='Data Sheet'!K41
A4: Sales | B4: ='Data Sheet'!B42 | C4: ='Data Sheet'!C42 | D4: ='Data Sheet'!D42 | E4: ='Data Sheet'!E42 | F4: ='Data Sheet'!F42 | G4: ='Data Sheet'!G42 | H4: ='Data Sheet'!H42 | I4: ='Data Sheet'!I42 | ... K4: ='Data Sheet'!K42
A5: Expenses | B5: ='Data Sheet'!B43 | C5: ='Data Sheet'!C43 | D5: ='Data Sheet'!D43 | E5: ='Data Sheet'!E43 | F5: ='Data Sheet'!F43 | G5: ='Data Sheet'!G43 | H5: ='Data Sheet'!H43 | I5: ='Data Sheet'!I43 | ... K5: ='Data Sheet'!K43
A6: Operating Profit | B6: ='Data Sheet'!B50 | C6: ='Data Sheet'!C50 | D6: ='Data Sheet'!D50 | E6: ='Data Sheet'!E50 | F6: ='Data Sheet'!F50 | G6: ='Data Sheet'!G50 | H6: ='Data Sheet'!H50 | I6: ='Data Sheet'!I50 | ... K6: ='Data Sheet'!K50
A7: Other Income | B7: ='Data Sheet'!B44 | C7: ='Data Sheet'!C44 | D7: ='Data Sheet'!D44 | E7: ='Data Sheet'!E44 | F7: ='Data Sheet'!F44 | G7: ='Data Sheet'!G44 | H7: ='Data Sheet'!H44 | I7: ='Data Sheet'!I44 | ... K7: ='Data Sheet'!K44
A8: Depreciation | B8: ='Data Sheet'!B45 | C8: ='Data Sheet'!C45 | D8: ='Data Sheet'!D45 | E8: ='Data Sheet'!E45 | F8: ='Data Sheet'!F45 | G8: ='Data Sheet'!G45 | H8: ='Data Sheet'!H45 | I8: ='Data Sheet'!I45 | ... K8: ='Data Sheet'!K45
A9: Interest | B9: ='Data Sheet'!B46 | C9: ='Data Sheet'!C46 | D9: ='Data Sheet'!D46 | E9: ='Data Sheet'!E46 | F9: ='Data Sheet'!F46 | G9: ='Data Sheet'!G46 | H9: ='Data Sheet'!H46 | I9: ='Data Sheet'!I46 | ... K9: ='Data Sheet'!K46
A10: Profit before tax | B10: ='Data Sheet'!B47 | C10: ='Data Sheet'!C47 | D10: ='Data Sheet'!D47 | E10: ='Data Sheet'!E47 | F10: ='Data Sheet'!F47 | G10: ='Data Sheet'!G47 | H10: ='Data Sheet'!H47 | I10: ='Data Sheet'!I47 | ... K10: ='Data Sheet'!K47
A11: Tax | B11: ='Data Sheet'!B48 | C11: ='Data Sheet'!C48 | D11: ='Data Sheet'!D48 | E11: ='Data Sheet'!E48 | F11: ='Data Sheet'!F48 | G11: ='Data Sheet'!G48 | H11: ='Data Sheet'!H48 | I11: ='Data Sheet'!I48 | ... K11: ='Data Sheet'!K48
A12: Net profit | B12: ='Data Sheet'!B49 | C12: ='Data Sheet'!C49 | D12: ='Data Sheet'!D49 | E12: ='Data Sheet'!E49 | F12: ='Data Sheet'!F49 | G12: ='Data Sheet'!G49 | H12: ='Data Sheet'!H49 | I12: ='Data Sheet'!I49 | ... K12: ='Data Sheet'!K49
A14: OPM | B14: =IF(B4>0,B6/B4,"") | C14: =IF(C4>0,C6/C4,"") | D14: =IF(D4>0,D6/D4,"") | E14: =IF(E4>0,E6/E4,"") | F14: =IF(F4>0,F6/F4,"") | G14: =IF(G4>0,G6/G4,"") | H14: =IF(H4>0,H6/H4,"") | I14: =IF(I4>0,I6/I4,"") | ... K14: =IF(K4>0,K6/K4,"")

Sheet Balance Sheet
A1: ='Profit & Loss'!A1 | E1: =UPDATE | J1: SCREENER.IN
A3: Narration | B3: ='Data Sheet'!B56 | C3: ='Data Sheet'!C56 | D3: ='Data Sheet'!D56 | E3: ='Data Sheet'!E56 | F3: ='Data Sheet'!F56 | G3: ='Data Sheet'!G56 | H3: ='Data Sheet'!H56 | I3: ='Data Sheet'!I56 | ... K3: ='Data Sheet'!K56
A4: Equity Share Capital | B4: ='Data Sheet'!B57 | C4: ='Data Sheet'!C57 | D4: ='Data Sheet'!D57 | E4: ='Data Sheet'!E57 | F4: ='Data Sheet'!F57 | G4: ='Data Sheet'!G57 | H4: ='Data Sheet'!H57 | I4: ='Data Sheet'!I57 | ... K4: ='Data Sheet'!K57
A5: Reserves | B5: ='Data Sheet'!B58 | C5: ='Data Sheet'!C58 | D5: ='Data Sheet'!D58 | E5: ='Data Sheet'!E58 | F5: ='Data Sheet'!F58 | G5: ='Data Sheet'!G58 | H5: ='Data Sheet'!H58 | I5: ='Data Sheet'!I58 | ... K5: ='Data Sheet'!K58
A6: Borrowings | B6: ='Data Sheet'!B59 | C6: ='Data Sheet'!C59 | D6: ='Data Sheet'!D59 | E6: ='Data Sheet'!E59 | F6: ='Data Sheet'!F59 | G6: ='Data Sheet'!G59 | H6: ='Data Sheet'!H59 | I6: ='Data Sheet'!I59 | ... K6: ='Data Sheet'!K59
A7: Other Liabilities | B7: ='Data Sheet'!B60 | C7: ='Data Sheet'!C60 | D7: ='Data Sheet'!D60 | E7: ='Data Sheet'!E60 | F7: ='Data Sheet'!F60 | G7: ='Data Sheet'!G60 | H7: ='Data Sheet'!H60 | I7: ='Data Sheet'!I60 | ... K7: ='Data Sheet'!K60
A8: Total | B8: ='Data Sheet'!B61 | C8: ='Data Sheet'!C61 | D8: ='Data Sheet'!D61 | E8: ='Data Sheet'!E61 | F8: ='Data Sheet'!F61 | G8: ='Data Sheet'!G61 | H8: ='Data Sheet'!H61 | I8: ='Data Sheet'!I61 | ... K8: ='Data Sheet'!K61
A10: Net Block | B10: ='Data Sheet'!B62 | C10: ='Data Sheet'!C62 | D10: ='Data Sheet'!D62 | E10: ='Data Sheet'!E62 | F10: ='Data Sheet'!F62 | G10: ='Data Sheet'!G62 | H10: ='Data Sheet'!H62 | I10: ='Data Sheet'!I62 | ... K10: ='Data Sheet'!K62
A11: Capital Work in Progress | B11: ='Data Sheet'!B63 | C11: ='Data Sheet'!C63 | D11: ='Data Sheet'!D63 | E11: ='Data Sheet'!E63 | F11: ='Data Sheet'!F63 | G11: ='Data Sheet'!G63 | H11: ='Data Sheet'!H63 | I11: ='Data Sheet'!I63 | ... K11: ='Data Sheet'!K63
A12: Investments | B12: ='Data Sheet'!B64 | C12: ='Data Sheet'!C64 | D12: ='Data Sheet'!D64 | E12: ='Data Sheet'!E64 | F12: ='Data Sheet'!F64 | G12: ='Data Sheet'!G64 | H12: ='Data Sheet'!H64 | I12: ='Data Sheet'!I64 | ... K12: ='Data Sheet'!K64
A13: Other Assets | B13: ='Data Sheet'!B65 | C13: ='Data Sheet'!C65 | D13: ='Data Sheet'!D65 | E13: ='Data Sheet'!E65 | F13: ='Data Sheet'!F65 | G13: ='Data Sheet'!G65 | H13: ='Data Sheet'!H65 | I13: ='Data Sheet'!I65 | ... K13: ='Data Sheet'!K65
A14: Total | B14: ='Data Sheet'!B66 | C14: ='Data Sheet'!C66 | D14: ='Data Sheet'!D66 | E14: ='Data Sheet'!E66 | F14: ='Data Sheet'!F66 | G14: ='Data Sheet'!G66 | H14: ='Data Sheet'!H66 | I14: ='Data Sheet'!I66 | ... K14: ='Data Sheet'!K66
A16: Working Capital | B16: =B13-B7 | C16: =C13-C7 | D16: =D13-D7 | E16: =E13-E7 | F16: =F13-F7 | G16: =G13-G7 | H16: =H13-H7 | I16: =I13-I7 | ... K16: =K13-K7
A17: Debtors | B17: ='Data Sheet'!B67 | C17: ='Data Sheet'!C67 | D17: ='Data Sheet'!D67 | E17: ='Data Sheet'!E67 | F17: ='Data Sheet'!F67 | G17: ='Data Sheet'!G67 | H17: ='Data Sheet'!H67 | I17: ='Data Sheet'!I67 | ... K17: ='Data Sheet'!K67
A18: Inventory | B18: ='Data Sheet'!B68 | C18: ='Data Sheet'!C68 | D18: ='Data Sheet'!D68 | E18: ='Data Sheet'!E68 | F18: ='Data Sheet'!F68 | G18: ='Data Sheet'!G68 | H18: ='Data Sheet'!H68 | I18: ='Data Sheet'!I68 | ... K18: ='Data Sheet'!K68
A20: Debtor Days | B20: =IF('Profit & Loss'!B4>0,'Balance Sheet'!B17/('Profit & Loss'!B4/365),0) | C20: =IF('Profit & Loss'!C4>0,'Balance Sheet'!C17/('Profit & Loss'!C4/365),0) | D20: =IF('Profit & Loss'!D4>0,'Balance Sheet'!D17/('Profit & Loss'!D4/365),0) | E20: =IF('Profit & Loss'!E4>0,'Balance Sheet'!E17/('Profit & Loss'!E4/365),0) | F20: =IF('Profit & Loss'!F4>0,'Balance Sheet'!F17/('Profit & Loss'!F4/365),0) | G20: =IF('Profit & Loss'!G4>0,'Balance Sheet'!G17/('Profit & Loss'!G4/365),0) | H20: =IF('Profit & Loss'!H4>0,'Balance Sheet'!H17/('Profit & Loss'!H4/365),0) | I20: =IF('Profit & Loss'!I4>0,'Balance Sheet'!I17/('Profit & Loss'!I4/365),0) | ... K20: =IF('Profit & Loss'!K4>0,'Balance Sheet'!K17/('Profit & Loss'!K4/365),0)
A21: Inventory Turnover | B21: =IF('Balance Sheet'!B18>0,'Profit & Loss'!B4/'Balance Sheet'!B18,0) | C21: =IF('Balance Sheet'!C18>0,'Profit & Loss'!C4/'Balance Sheet'!C18,0) | D21: =IF('Balance Sheet'!D18>0,'Profit & Loss'!D4/'Balance Sheet'!D18,0) | E21: =IF('Balance Sheet'!E18>0,'Profit & Loss'!E4/'Balance Sheet'!E18,0) | F21: =IF('Balance Sheet'!F18>0,'Profit & Loss'!F4/'Balance Sheet'!F18,0) | G21: =IF('Balance Sheet'!G18>0,'Profit & Loss'!G4/'Balance Sheet'!G18,0) | H21: =IF('Balance Sheet'!H18>0,'Profit & Loss'!H4/'Balance Sheet'!H18,0) | I21: =IF('Balance Sheet'!I18>0,'Profit & Loss'!I4/'Balance Sheet'!I18,0) | ... K21: =IF('Balance Sheet'!K18>0,'Profit & Loss'!K4/'Balance Sheet'!K18,0)
A23: Return on Equity | B23: =IF(SUM('Balance Sheet'!B4:B5)>0,'Profit & Loss'!B12/SUM('Balance Sheet'!B4:B5),"") | C23: =IF(SUM('Balance Sheet'!C4:C5)>0,'Profit & Loss'!C12/SUM('Balance Sheet'!C4:C5),"") | D23: =IF(SUM('Balance Sheet'!D4:D5)>0,'Profit & Loss'!D12/SUM('Balance Sheet'!D4:D5),"") | E23: =IF(SUM('Balance Sheet'!E4:E5)>0,'Profit & Loss'!E12/SUM('Balance Sheet'!E4:E5),"") | F23: =IF(SUM('Balance Sheet'!F4:F5)>0,'Profit & Loss'!F12/SUM('Balance Sheet'!F4:F5),"") | G23: =IF(SUM('Balance Sheet'!G4:G5)>0,'Profit & Loss'!G12/SUM('Balance Sheet'!G4:G5),"") | H23: =IF(SUM('Balance Sheet'!H4:H5)>0,'Profit & Loss'!H12/SUM('Balance Sheet'!H4:H5),"") | I23: =IF(SUM('Balance Sheet'!I4:I5)>0,'Profit & Loss'!I12/SUM('Balance Sheet'!I4:I5),"") | ... K23: =IF(SUM('Balance Sheet'!K4:K5)>0,'Profit & Loss'!K12/SUM('Balance Sheet'!K4:K5),"")
A24: Return on Capital Emp | C24: =IF((B4+B5+B6+C4+C5+C6)>0,('Profit & Loss'!C10+'Profit & Loss'!C9)*2/(B4+B5+B6+C4+C5+C6),"") | D24: =IF((C4+C5+C6+D4+D5+D6)>0,('Profit & Loss'!D10+'Profit & Loss'!D9)*2/(C4+C5+C6+D4+D5+D6),"") | E24: =IF((D4+D5+D6+E4+E5+E6)>0,('Profit & Loss'!E10+'Profit & Loss'!E9)*2/(D4+D5+D6+E4+E5+E6),"") | F24: =IF((E4+E5+E6+F4+F5+F6)>0,('Profit & Loss'!F10+'Profit & Loss'!F9)*2/(E4+E5+E6+F4+F5+F6),"") | G24: =IF((F4+F5+F6+G4+G5+G6)>0,('Profit & Loss'!G10+'Profit & Loss'!G9)*2/(F4+F5+F6+G4+G5+G6),"") | H24: =IF((G4+G5+G6+H4+H5+H6)>0,('Profit & Loss'!H10+'Profit & Loss'!H9)*2/(G4+G5+G6+H4+H5+H6),"") | I24: =IF((H4+H5+H6+I4+I5+I6)>0,('Profit & Loss'!I10+'Profit & Loss'!I9)*2/(H4+H5+H6+I4+I5+I6),"") | J24: =IF((I4+I5+I6+J4+J5+J6)>0,('Profit & Loss'!J10+'Profit & Loss'!J9)*2/(I4+I5+I6+J4+J5+J6),"") | K24: =IF((J4+J5+J6+K4+K5+K6)>0,('Profit & Loss'!K10+'Profit & Loss'!K9)*2/(J4+J5+J6+K4+K5+K6),"")
A28: NFA AVG | C28: =AVERAGE(C10,B10) | D28: =AVERAGE(D10,C10) | E28: =AVERAGE(E10,D10) | F28: =AVERAGE(F10,E10) | G28: =AVERAGE(G10,F10) | H28: =AVERAGE(H10,G10) | I28: =AVERAGE(I10,H10) | J28: =AVERAGE(J10,I10) | K28: =AVERAGE(K10,J10)
A29: CWIP/Gross Block(%) | B29: =(B11/(B10+'Profit & Loss'!B8))*100 | C29: =(C11/(C10+'Profit & Loss'!C8))*100 | D29: =(D11/(D10+'Profit & Loss'!D8))*100 | E29: =(E11/(E10+'Profit & Loss'!E8))*100 | F29: =(F11/(F10+'Profit & Loss'!F8))*100 | G29: =(G11/(G10+'Profit & Loss'!G8))*100 | H29: =(H11/(H10+'Profit & Loss'!H8))*100 | I29: =(I11/(I10+'Profit & Loss'!I8))*100 | ... K29: =(K11/(K10+'Profit & Loss'!K8))*100

Sheet Cash Flow
A1: ='Balance Sheet'!A1 | E1: =UPDATE | J1: SCREENER.IN
A3: Narration | B3: ='Data Sheet'!B81 | C3: ='Data Sheet'!C81 | D3: ='Data Sheet'!D81 | E3: ='Data Sheet'!E81 | F3: ='Data Sheet'!F81 | G3: ='Data Sheet'!G81 | H3: ='Data Sheet'!H81 | I3: ='Data Sheet'!I81 | ... K3: ='Data Sheet'!K81
A4: Cash from Operating Activity | B4: ='Data Sheet'!B82 | C4: ='Data Sheet'!C82 | D4: ='Data Sheet'!D82 | E4: ='Data Sheet'!E82 | F4: ='Data Sheet'!F82 | G4: ='Data Sheet'!G82 | H4: ='Data Sheet'!H82 | I4: ='Data Sheet'!I82 | ... K4: ='Data Sheet'!K82 | L4: =SUM(B4:K4)
A5: Cash from Investing Activity | B5: ='Data Sheet'!B83 | C5: ='Data Sheet'!C83 | D5: ='Data Sheet'!D83 | E5: ='Data Sheet'!E83 | F5: ='Data Sheet'!F83 | G5: ='Data Sheet'!G83 | H5: ='Data Sheet'!H83 | I5: ='Data Sheet'!I83 | ... K5: ='Data Sheet'!K83
A6: Cash from Financing Activity | B6: ='Data Sheet'!B84 | C6: ='Data Sheet'!C84 | D6: ='Data Sheet'!D84 | E6: ='Data Sheet'!E84 | F6: ='Data Sheet'!F84 | G6: ='Data Sheet'!G84 | H6: ='Data Sheet'!H84 | I6: ='Data Sheet'!I84 | ... K6: ='Data Sheet'!K84
A7: Net Cash Flow | B7: ='Data Sheet'!B85 | C7: ='Data Sheet'!C85 | D7: ='Data Sheet'!D85 | E7: ='Data Sheet'!E85 | F7: ='Data Sheet'!F85 | G7: ='Data Sheet'!G85 | H7: ='Data Sheet'!H85 | I7: ='Data Sheet'!I85 | ... K7: ='Data Sheet'!K85 | L7: =SUM(B7:K7)
A9: CFO as % of EBITDA | B9: =(B4/'Profit & Loss'!C6)*100 | C9: =(C4/'Profit & Loss'!D6)*100 | D9: =(D4/'Profit & Loss'!E6)*100 | E9: =(E4/'Profit & Loss'!F6)*100 | F9: =(F4/'Profit & Loss'!G6)*100 | G9: =(G4/'Profit & Loss'!H6)*100 | H9: =(H4/'Profit & Loss'!I6)*100 | I9: =(I4/'Profit & Loss'!J6)*100 | ... K9: =(K4/'Profit & Loss'!L6)*100 | L9: =(L4/'Profit & Loss'!O6)*100
A10: CFO as % of EBITDA last 5 years | B10: =AVERAGE(K9,J9,I9,H9,G9)

Sheet Customization
A1: How to use it?
A3: You can customize this workbook as you want.
B4: You can add custom formating, add conditional formating, add your own formulas… do ANYTHING.
B5: Please don't edit the "Data Sheet" only.
A7: After customization, you can upload this back on Screener.
B8: Upload on: | C8: https://www.screener.in/excel/
A10: Download your customized workbooks now onwards.
B11: Now whenever you will "Export to excel" from Screener, it will export your customized file.
A14: TESTING:
B15: This is a testing feature currently.
B16: You can report any formula errors on the worksheet at: support@screener.in

Sheet Data Sheet
A1: COMPANY NAME | B1: TATA CONSULTANCY SERVICES LTD | E1: =IF(B2<>B3, "A NEW VERSION OF THE WORKSHEET IS AVAILABLE", "")
A2: LATEST VERSION | B2: 2.1 | E2: PLEASE DO NOT MAKE ANY CHANGES TO THIS SHEET
A3: CURRENT VERSION | B3: 2.1
A5: META
A6: Number of shares | B6: =IF(B9>0, B9/B8, 0)
A7: Face Value | B7: 1
A8: Current Price | B8: 2452.7
A9: Market Capitalization | B9: 887408.33
A15: PROFIT & LOSS
A16: Report Date | B16: 42825 | C16: 43190 | D16: 43555 | E16: 43921 | F16: 44286 | G16: 44651 | H16: 45016 | I16: 45382 | J16: 45747 | K16: 46112
A17: Sales | B17: 117966 | C17: 123104 | D17: 146463 | E17: 156949 | F17: 164177 | G17: 191754 | H17: 225458 | I17: 240893 | J17: 255324 | K17: 267021
A18: Raw Material Cost | B18: 94 | C18: 86 | D18: 40 | E18: 18 | F18: 14 | G18: 29 | H18: 37 | I18: 42 | J18: 49 | K18: 43
A19: Change in Inventory | B19: 1
A20: Power and Fuel
A21: Other Mfr. Exp | B21: 2715 | C21: 2614 | D21: 2230 | E21: 1887 | F21: 1448 | G21: 1134 | H21: 1844 | I21: 3660 | J21: 11599 | K21: 4356
A22: Employee Cost | B22: 61621 | C22: 66396 | D22: 78246 | E22: 85952 | F22: 91814 | G22: 107554 | H22: 127522 | I22: 140131 | J22: 145788 | K22: 154994
A23: Selling and admin | B23: 16392 | C23: 16808 | D23: 20387 | E23: 20527 | F23: 18322 | G23: 23187 | H23: 28913 | I23: 24151 | J23: 20729 | K23: 24434
A24: Other Expenses | B24: 4834 | C24: 4684 | D24: 6054 | E24: 6456 | F24: 6033 | G24: 6793 | H24: 7883 | I24: 8613 | J24: 9752 | K24: 10796
A25: Other Income | B25: 4221 | C25: 3642 | D25: 4311 | E25: 4592 | F25: 1916 | G25: 4018 | H25: 3449 | I25: 3464 | J25: 3962 | K25: -124
A26: Depreciation | B26: 1987 | C26: 2014 | D26: 2056 | E26: 3529 | F26: 4065 | G26: 4604 | H26: 5022 | I26: 4985 | J26: 5242 | K26: 5560
A27: Interest | B27: 32 | C27: 52 | D27: 198 | E27: 924 | F27: 637 | G27: 784 | H27: 779 | I27: 778 | J27: 796 | K27: 1227
A28: Profit before tax | B28: 34513 | C28: 34092 | D28: 41563 | E28: 42248 | F28: 43760 | G28: 51687 | H28: 56907 | I28: 61997 | J28: 65331 | K28: 65487
A29: Tax | B29: 8156 | C29: 8212 | D29: 10001 | E29: 9801 | F29: 11198 | G29: 13238 | H29: 14604 | I29: 15898 | J29: 16534 | K29: 16033
A30: Net profit | B30: 26289 | C30: 25826 | D30: 31472 | E30: 32340 | F30: 32430 | G30: 38327 | H30: 42147 | I30: 45908 | J30: 48553 | K30: 49210
A31: Dividend Amount | B31: 9259 | C31: 9550 | D31: 11250 | E31: 27375 | F31: 14060 | G31: 15738 | H31: 42090 | I31: 26426 | J31: 45612 | K31: 39820
A40: Quarters
A41: Report Date | B41: 45382 | C41: 45473 | D41: 45565 | E41: 45657 | F41: 45747 | G41: 45838 | H41: 45930 | I41: 46022 | J41: 46112 | K41: 46203
A42: Sales | B42: 61237 | C42: 62613 | D42: 64259 | E42: 63973 | F42: 64479 | G42: 63437 | H42: 65799 | I42: 67087 | J42: 70698 | K42: 72275
A43: Expenses | B43: 44073 | C43: 45951 | D43: 47528 | E43: 46939 | F43: 47499 | G43: 46562 | H43: 47821 | I43: 48818 | J43: 51422 | K43: 53719
A44: Other Income | B44: 1157 | C44: 962 | D44: 729 | E44: 1243 | F44: 1028 | G44: 1660 | H44: -268 | I44: -2273 | J44: 757 | K44: 900
A45: Depreciation | B45: 1246 | C45: 1220 | D45: 1266 | E45: 1377 | F45: 1379 | G45: 1361 | H45: 1413 | I45: 1380 | J45: 1406 | K45: 1239
A46: Interest | B46: 226 | C46: 173 | D46: 162 | E46: 234 | F46: 227 | G46: 195 | H46: 229 | I46: 538 | J46: 265 | K46: 273
A47: Profit before tax | B47: 16849 | C47: 16231 | D47: 16032 | E47: 16666 | F47: 16402 | G47: 16979 | H47: 16068 | I47: 14078 | J47: 18362 | K47: 17944
A48: Tax | B48: 4347 | C48: 4126 | D48: 4077 | E48: 4222 | F48: 4109 | G48: 4160 | H48: 3937 | I48: 3358 | J48: 4578 | K48: 4524
A49: Net profit | B49: 12434 | C49: 12040 | D49: 11909 | E49: 12380 | F49: 12224 | G49: 12760 | H49: 12075 | I49: 10657 | J49: 13718 | K49: 13349
A50: Operating Profit | B50: 17164 | C50: 16662 | D50: 16731 | E50: 17034 | F50: 16980 | G50: 16875 | H50: 17978 | I50: 18269 | J50: 19276 | K50: 18556
A55: BALANCE SHEET
A56: Report Date | B56: 42825 | C56: 43190 | D56: 43555 | E56: 43921 | F56: 44286 | G56: 44651 | H56: 45016 | I56: 45382 | J56: 45747 | K56: 46112
A57: Equity Share Capital | B57: 197 | C57: 191 | D57: 375 | E57: 375 | F57: 370 | G57: 366 | H57: 366 | I57: 362 | J57: 362 | K57: 362
A58: Reserves | B58: 86017 | C58: 84937 | D58: 89071 | E58: 83751 | F58: 86063 | G58: 88773 | H58: 90058 | I58: 90127 | J58: 94394 | K58: 106878
...
